Workbook

Sheet Summary
A1: Показатель | B1: Год 1 | C1: Год 2 | D1: Год 3 | E1: Комментарий
A2: Ключевые метрики
A3: Платящих мастеров на конец года | B3: ='3 года подробно'!N10 -> 672.63953 | C3: ='3 года подробно'!Z10 -> 1312.4359 | D3: ='3 года подробно'!AL10 -> 1996.3875 | E3: Главная метрика роста
A4: Новых мастеров на пробном периоде за год | B4: =SUM('3 года подробно'!B7:N7) -> 2010.7248 | C4: =SUM('3 года подробно'!O7:Z7) -> 2598.8879 | D4: =SUM('3 года подробно'!AA7:AL7) -> 2932.6195 | E4: Из рекламы и без неё (сарафан, рекомендации)
A5: Доля SAM на платной подписке | B5: ='3 года подробно'!N11 -> 0.024638811 | C5: ='3 года подробно'!Z11 -> 0.048074576 | D5: ='3 года подробно'!AL11 -> 0.073127748 | E5: SAM — лист «Вводные», строка 6
A6: Постоянных клиентов на конец года | B6: ='3 года подробно'!N18 -> 7487.4399 | C6: ='3 года подробно'!Z18 -> 12007.503 | D6: ='3 года подробно'!AL18 -> 16176.572
A7: Записей через платформу за год | B7: =SUM('3 года подробно'!B19:N19) -> 64435.68 | C7: =SUM('3 года подробно'!O19:Z19) -> 150495.07 | D7: =SUM('3 года подробно'!AA19:AL19) -> 218310.23
A8: Записей на мастера в месяц (конец года) | B8: ='3 года подробно'!N20 -> 13.851287 | C8: ='3 года подробно'!Z20 -> 11.570861 | D8: ='3 года подробно'!AL20 -> 10.361145 | E8: [цель команды] 10+ записей на мастера в месяц, с учётом собственных клиентов мастера. Проверить на пилоте
A9: Записей из каталога на мастера в месяц (конец года) | B9: ='3 года подробно'!N53 -> 2.679192 | C9: ='3 года подробно'!Z53 -> 2.9818223 | D9: ='3 года подробно'!AL53 -> 3.2978145 | E9: Новые клиенты из каталога и их повторные визиты, без клиентов, которых мастер перенёс сам. Цель — Вводные, строка 63
A10: GMV: оборот записей через платформу | B10: =SUM('3 года подробно'!B21:N21) -> 2.0554982e+08 | C10: =SUM('3 года подробно'!O21:Z21) -> 4.8007929e+08 | D10: =SUM('3 года подробно'!AA21:AL21) -> 6.9640963e+08 | E10: Сколько мастера заработали на записях через Камертон. Это не выручка Камертона
A11: Доходы
A12: Выручка от подписок | B12: =SUM('3 года подробно'!B24:N24) -> 4172765.4 | C12: =SUM('3 года подробно'!O24:Z24) -> 12063115 | D12: =SUM('3 года подробно'!AA24:AL24) -> 19963369
A13: Выручка от продвижения | B13: =SUM('3 года подробно'!B25:N25) -> 914650.31 | C13: =SUM('3 года подробно'!O25:Z25) -> 3943397.9 | D13: =SUM('3 года подробно'!AA25:AL25) -> 7242653.2
A14: НДС на УСН (вычитается из выручки) | B14: =SUM('3 года подробно'!B27:N27) -> 0 | C14: =SUM('3 года подробно'!O27:Z27) -> 0 | D14: =SUM('3 года подробно'!AA27:AL27) -> 1295524.9 | E14: 5% в цене с месяца после превышения порога освобождения (Вводные, строки 74–77)
A15: Выручка всего без НДС | B15: =SUM('3 года подробно'!B26:N26) -> 5087415.7 | C15: =SUM('3 года подробно'!O26:Z26) -> 16006513 | D15: =SUM('3 года подробно'!AA26:AL26) -> 25910498
A16: Рост выручки | C16: =IFERROR(C15/B15-1,0) -> 2.1462954 | D16: =IFERROR(D15/C15-1,0) -> 0.6187472
A17: Расходы
A18: OPEX | B18: =SUM('3 года подробно'!B29:N29) -> 4501468 | C18: =SUM('3 года подробно'!O29:Z29) -> 4501468 | D18: =SUM('3 года подробно'!AA29:AL29) -> 4501468 | E18: Техподдержка, хостинг, команда после запуска, бухгалтерия и юрист
A19: Маркетинг | B19: =SUM('3 года подробно'!B30:N30) -> 2806669.9 | C19: =SUM('3 года подробно'!O30:Z30) -> 3673823.3 | D19: =SUM('3 года подробно'!AA30:AL30) -> 4879363.6 | E19: Лист «Маркетинг»; клиентские каналы растут вместе с числом мастеров
A20: Разработка | B20: =SUM('3 года подробно'!B31:N31) -> 3085641 | C20: =SUM('3 года подробно'!O31:Z31) -> 0 | D20: =SUM('3 года подробно'!AA31:AL31) -> 0 | E20: Разработка MVP — разовые вложения в месяц 0
A21: Переменные расходы на обслуживание | B21: =SUM('3 года подробно'!B32:N32) -> 702858.27 | C21: =SUM('3 года подробно'!O32:Z32) -> 1391808.8 | D21: =SUM('3 года подробно'!AA32:AL32) -> 1963855.6 | E21: Проверка новых мастеров, SMS-напоминания, эквайринг
A22: Прибыль
A23: Прибыль до налога | B23: =SUM('3 года подробно'!B35:N35) -> -6009221.5 | C23: =SUM('3 года подробно'!O35:Z35) -> 6439412.6 | D23: =SUM('3 года подробно'!AA35:AL35) -> 14565810 | E23: Выручка минус OPEX, маркетинг, разработка и обслуживание
A24: Налог | B24: =SUM('3 года подробно'!B37:N37) -> 50874.157 | C24: =SUM('3 года подробно'!O37:Z37) -> 160065.13 | D24: =SUM('3 года подробно'!AA37:AL37) -> 2184871.6 | E24: УСН 15% с годовой прибыли за вычетом убытков прошлых лет; если меньше — минимальный налог 1% от годовой выручки (НК РФ, ст. 346.18)
A25: Чистая прибыль за год | B25: =SUM('3 года подробно'!B40:N40) -> -6060095.6 | C25: =SUM('3 года подробно'!O40:Z40) -> 6279347.5 | D25: =SUM('3 года подробно'!AA40:AL40) -> 12380939
A26: Чистая маржа | B26: =IFERROR(B25/B15,0) -> -1.1911933 | C26: =IFERROR(C25/C15,0) -> 0.39229953 | D26: =IFERROR(D25/D15,0) -> 0.47783486
A27: Накопленная прибыль | B27: ='3 года подробно'!N41 -> -6060095.6 | C27: ='3 года подробно'!Z41 -> 219251.82 | D27: ='3 года подробно'!AL41 -> 12600191 | E27: На конец года
A28: ROI: чистая прибыль на рубль затрат | B28: =IFERROR(B25/SUM(B18:B21),0) -> -0.54612001 | C28: =IFERROR(SUM(B25:C25)/SUM(B18:C21),0) -> 0.010610463 | D28: =IFERROR(SUM(B25:D25)/SUM(B18:D21),0) -> 0.39365232 | E28: Чистая прибыль / (OPEX + маркетинг + разработка + обслуживание); годы 2 и 3 — нарастающим итогом
A29: Потребность в инвестициях | B29: =-MIN(0,MIN('3 года подробно'!B41:AL41)) -> 6258272 | E29: Самый глубокий минус накопленной прибыли: столько денег нужно, чтобы дойти до окупаемости
A30: Срок окупаемости | B30: =IFERROR(MATCH(TRUE(),INDEX('3 года подробно'!C41:AL41>0,0),0),"после 36") -> 24 | C30: месяц | E30: Первый месяц, в котором накопленная прибыль стала положительной
A31: Юнит-экономика мастера
A32: ARPU: выручка с платящего мастера | B32: =Вводные!$B$21+AVERAGE('3 года подробно'!F57:AL57)*Вводные!$B$22 -> 1294.6118 | C32: ₽/мес | E32: Подписка + продвижение × средняя доля покупающих за месяцы 4–36
A33: CAC: привлечение платящего мастера | B33: =IFERROR(SUM(Маркетинг!B15:N15)/(SUM('3 года подробно'!B8:N8)*SUM('3 года подробно'!B5:N5)/SUM('3 года подробно'!B7:N7)),0) -> 3074.4158 | C33: ₽ | E33: Расходы на привлечение мастеров за 1-й год / новые платящие мастера из рекламы, с учётом насыщения рынка и холодного старта
A34: LTV: маржа с мастера за время жизни | B34: =IFERROR(($B$32*(1-Вводные!$B$26)-AVERAGE('3 года подробно'!C20:AL20)*OPEX!$C$11)/AVERAGE('3 года подробно'!C56:AL56),0) -> 33431.669 | C34: ₽ | E34: (ARPU − эквайринг − SMS-напоминания по записям мастера) / средний отток за 3 года
A35: LTV / CAC | B35: =IFERROR(B34/B33,0) -> 10.874153 | E35: Ориентир — не меньше 3
A36: Проверка | B36: =IF(B34>3*B33,"LTV больше 3*CAC","LTV меньше 3*CAC") -> LTV больше 3*CAC

Sheet Вводные
A1: Параметр | B1: Значение | C1: Ед. | D1: Источник / комментарий
A2: Рынок Москвы
A3: Частные бьюти-мастера в Москве | B3: 65000 | C3: мастеров | D3: Более 50 тыс. самозанятых в бьюти (ДПиИР Москвы через РБК, 2025) + мастера без регистрации; коридор 50–85 тыс. — оценка команды (ссылка — лист «Источники»)
A4: Доля мастеров в наших услугах (ногти, брови/ресницы, волосы, макияж) | B4: 0.7 | C4: % | D4: [допущение] Первоисточника нет: доля мастеров ногтей, бровей/ресниц, волос и макияжа среди всех бьюти-мастеров. Проверить на пилоте
A5: Доля мастеров, которые ищут клиентов и записывают онлайн | B5: 0.6 | C5: % | D5: [допущение] Опора: 42% мастеров искали клиентов на Авито уже в 2022 (Data Insight через Коммерсантъ) (ссылка — лист «Источники»)
A6: SAM: мастера, которым нужен Камертон | B6: =B3*B4*B5 -> 27300 | C6: мастеров | D6: Расчёт: мастера × доля наших услуг × доля ищущих клиентов онлайн
A7: Средний чек бьюти-услуги в Москве | B7: 3190 | C7: ₽ | D7: СберАналитика, янв.–нояб. 2025 (ссылка — лист «Источники»)
A8: Визитов постоянного клиента в год | B8: 14 | C8: визитов | D8: Опрос Авито, 10 000 женщин, через Mail.ru (ссылка — лист «Источники»)
A9: Воронка мастеров
A10: Регистрации мастеров без рекламы (сарафан, чаты, знакомые) | B10: 25 | C10: мастеров/мес | D10: [допущение] Постоянный поток без рекламы с первого месяца: знакомые команды, чаты и каналы мастеров, колледжи. Сарафан, который растёт с базой, считается отдельно (строка 55)
A11: Конверсия пробного периода в платную подписку | B11: 0.371 | C11: % | D11: Visionary Marketing, 2026 (84 200 пробных периодов, 38 SaaS-компаний): с помощью менеджера в пробный период (PLG + sales-assist) — 30,5%, без помощи — 22,1%; пробный период 14 дней — 28,4% против 21,8% у 30 дней (+6,6 п.п.). Берём 30,5% + 6,6 п.п. = 37,1%. Прибавляем разницу, а не умножаем (30,5% × 28,4/21,8 = 39,7%), чтобы не переоценить: эффекты из одного исследования могут пересекаться. Менеджер по привлечению мастеров (OPEX) созванивается с каждым новым мастером. Проверим на пилоте
A12: Отток платящих мастеров в 1-й месяц после запуска | B12: 0.05 | C12: % в месяц | D12: SaaStr: очень малый бизнес уходит с темпом 3–5% в месяц. На старте берём верхнюю границу 5%: продукт сырой, отзывов и клиентов в каталоге мало. Дальше отток снижается к 3% (строки 69–70) (ссылка — лист «Источники»)
A13: Клиенты и матчинг
A14: Клиентов, которых мастер переносит на платформу при подключении | B14: =ROUND(B38*B39,0) -> 13 | C14: клиентов | D14: Расчёт: постоянных клиентов у мастера × доля, которую он переносит на платформу (расчёт ниже)
A15: Доля первых визитов с оценкой «совпали» | B15: 0.6 | C15: % | D15: [цель команды] Контекст: 64% клиентов имеют постоянного мастера, 39% выбирают по личным качествам (Анкетолог, 2021). Проверить на пилоте (ссылка — лист «Источники»)
A16: Повторная запись, если совпали | B16: 0.4 | C16: % | D16: [допущение] Вдвое выше среднего по рынку (20%, строка ниже): подбор по манере — главная ценность продукта. Уточним на пилоте
A17: Повторная запись, если не совпали | B17: 0.2 | C17: % | D17: Арника CRM (crmindex.ru): через месяц после первого визита возвращаются около 20% клиентов (ссылка — лист «Источники»)
A18: Итоговая доля клиентов, которые возвращаются | B18: =B15*B16+(1-B15)*B17 -> 0.32 | C18: % | D18: Расчёт: совпали × повтор при совпадении + не совпали × повтор без совпадения. Через эту долю подбор по манере влияет на число записей
A19: Отток постоянных клиентов | B19: =1-(B42/B41)^(1/11) -> 0.10367488 | C19: % в месяц | D19: Расчёт: из 20% вернувшихся через год остаются 6% — это отток около 10% в месяц (расчёт ниже)
A20: Монетизация
A21: Подписка мастера | B21: 990 | C21: ₽/мес | D21: [решение команды] Ориентир: YCLIENTS для частного специалиста от 1 600 ₽/мес (Webgard) (ссылка — лист «Источники»)
A22: Продвижение профиля в каталоге | B22: 1490 | C22: ₽/мес | D22: [решение команды] Ориентир: Профи.ру берёт с мастера ≈50–300 ₽ за отклик (HelmePro) (ссылка — лист «Источники»)
A23: Потолок доли платящих мастеров, покупающих продвижение | B23: 0.25 | C23: % | D23: [решение команды] Опора: опрос Авито (10 тыс. человек, март 2026) — 41% исполнителей в России платят за продвижение (31% до 5 тыс. ₽/мес, 10% — 5–10 тыс. ₽), в Петербурге 49%; средний бюджет 8,8 тыс. ₽/мес. Это все каналы сразу, каталог получит часть: берём ≈60% от 41%. Доля растёт с базой мастеров (строка 71) (ссылка — лист «Источники»)
A24: Продвижение запускается с месяца | B24: 4 | C24: мес. | D24: [допущение] Клиенты приходят в каталог с 3-го месяца (лист «Маркетинг»), продвижение имеет смысл со следующего
A25: Экономические параметры
A26: Эквайринг | B26: =B44*(1+B45) -> 0.0427 | C26: % от выручки | D26: Расчёт: комиссия ЮKassa по картам + НДС с комиссии, который на УСН не принимается к вычету (расчёт ниже)
A27: Налог УСН «доходы минус расходы» | B27: 0.15 | C27: % | D27: НК РФ (ссылка — лист «Источники»)
A28: Минимальный налог УСН | B28: 0.01 | C28: % от выручки | D28: НК РФ: платится, даже если прибыли нет (ссылка — лист «Источники»)
A29: Внедрение
A30: OPEX запускается с месяца | B30: 1 | C30: мес. | D30: [допущение] OPEX начинается с запуска продукта в месяце 1
A31: Страховые взносы на ФОТ | B31: 0.3 | C31: % | D31: НК РФ, общий тариф (ссылка — лист «Источники»)
A32: Резерв на непредвиденные работы разработки | B32: 0.2 | C32: % | D32: PMI: резерв 20% бюджета проекта — 10% на известные риски и 10% на неизвестные (ссылка — лист «Источники»)
A33: Ставка разработчика на поддержку и доработки после MVP | B33: 0.25 | C33: ставки | D33: [решение команды] После запуска нужен свой разработчик на четверть ставки: крупных изменений после запуска не планируется: исправления, доработки, новые функции. Зарплата — медиана разработчика в Москве (Разработка!B4) с взносами. Сверка: Edana, 2026 — поддержка ПО обходится в 15–25% стоимости разработки в год (0,5–0,8 млн ₽); четверть ставки (≈1,05 млн ₽ в год) покрывает поддержку с небольшим запасом на доработки (ссылка — лист «Источники»)
A34: Сокращение трудозатрат разработки за счёт ИИ-инструментов | B34: 0.4 | C34: % часов | D34: McKinsey, 2023: с генеративным ИИ код пишется на 35–45% быстрее; GitHub, 2023: с Copilot задача выполнена на 55,8% быстрее. Берём 40%. Продукт пишется с нуля — ближе к условиям этих исследований; прототип уже собран с помощью ИИ. Не применяется к работе менеджера продукта (ссылка — лист «Источники»)
A35: Расчёты для вводных
A36: Медианный доход частного мастера в Москве | B36: 166200 | C36: ₽/мес | D36: YCLIENTS через Коммерсантъ, март 2026 (ссылка — лист «Источники»)
A37: Визитов у мастера в месяц | B37: =B36/B7 -> 52.100313 | C37: визитов | D37: Расчёт: доход / средний чек
A38: Постоянных клиентов у одного мастера | B38: =B37/(B8/12) -> 44.657412 | C38: клиентов | D38: Расчёт: визиты мастера в месяц / визиты одного клиента в месяц
A39: Доля базы, которую мастер переносит на платформу при подключении | B39: 0.3 | C39: % | D39: [допущение] Не все клиенты готовы записываться через новый сервис; уточним на пилоте
A41: Возвращаются в течение месяца после первого визита | B41: 0.2 | C41: % | D41: Арника CRM (crmindex.ru, 2021) (ссылка — лист «Источники»)
...

Sheet 3 года подробно
A1: Показатель | B1: Месяц 0 | C1: Месяц 1 | D1: Месяц 2 | E1: Месяц 3 | F1: Месяц 4 | G1: Месяц 5 | H1: Месяц 6 | I1: Месяц 7 | J1: Месяц 8 | K1: Месяц 9 | L1: Месяц 10 | M1: Месяц 11 | N1: Месяц 12 | O1: Месяц 13 | P1: Месяц 14 | Q1: Месяц 15 | R1: Месяц 16 | S1: Месяц 17 | T1: Месяц 18 | U1: Месяц 19 | V1: Месяц 20 | W1: Месяц 21 | X1: Месяц 22 | Y1: Месяц 23 | Z1: Месяц 24 | AA1: Месяц 25 | AB1: Месяц 26 | AC1: Месяц 27 | AD1: Месяц 28 | AE1: Месяц 29 | AF1: Месяц 30 | AG1: Месяц 31 | AH1: Месяц 32 | AI1: Месяц 33 | AJ1: Месяц 34 | AK1: Месяц 35 | AL1: Месяц 36
A2: Номер месяца | B2: 0 | C2: 1 | D2: 2 | E2: 3 | F2: 4 | G2: 5 | H2: 6 | I2: 7 | J2: 8 | K2: 9 | L2: 10 | M2: 11 | N2: 12 | O2: 13 | P2: 14 | Q2: 15 | R2: 16 | S2: 17 | T2: 18 | U2: 19 | V2: 20 | W2: 21 | X2: 22 | Y2: 23 | Z2: 24 | AA2: 25 | AB2: 26 | AC2: 27 | AD2: 28 | AE2: 29 | AF2: 30 | AG2: 31 | AH2: 32 | AI2: 33 | AJ2: 34 | AK2: 35 | AL2: 36
A4: Мастера
A5: Регистрации мастеров из маркетинга (с учётом насыщения и холодного старта) | B5: =Маркетинг!B14*B44*B47 -> 0 | C5: =Маркетинг!C14*C44*C47 -> 94.850331 | D5: =Маркетинг!D14*D44*D47 -> 117.39583 | E5: =Маркетинг!E14*E44*E47 -> 120.75557 | F5: =Маркетинг!F14*F44*F47 -> 124.15873 | G5: =Маркетинг!G14*G44*G47 -> 128.82422 | H5: =Маркетинг!H14*H44*H47 -> 132.70815 | I5: =Маркетинг!I14*I44*I47 -> 136.137 | ... AL5: =Маркетинг!AL14*AL44*AL47 -> 159.55167
A6: Регистрации мастеров без рекламы: базовый поток + рекомендации (с учётом насыщения) | B6: 0 | C6: =(Вводные!$B$10+Вводные!$B$55*B10)*C44 -> 25 | D6: =(Вводные!$B$10+Вводные!$B$55*C10)*D44 -> 25.926035 | E6: =(Вводные!$B$10+Вводные!$B$55*D10)*E44 -> 27.793848 | F6: =(Вводные!$B$10+Вводные!$B$55*E10)*F44 -> 29.766545 | G6: =(Вводные!$B$10+Вводные!$B$55*F10)*G44 -> 32.636746 | H6: =(Вводные!$B$10+Вводные!$B$55*G10)*H44 -> 35.213584 | I6: =(Вводные!$B$10+Вводные!$B$55*H10)*I44 -> 37.673067 | J6: =(Вводные!$B$10+Вводные!$B$55*I10)*J44 -> 40.03752 | ... AL6: =(Вводные!$B$10+Вводные!$B$55*AK10)*AL44 -> 95.257316
A7: Новых мастеров на пробном периоде | B7: =B5+B6 -> 0 | C7: =C5+C6 -> 119.85033 | D7: =D5+D6 -> 143.32186 | E7: =E5+E6 -> 148.54941 | F7: =F5+F6 -> 153.92527 | G7: =G5+G6 -> 161.46097 | H7: =H5+H6 -> 167.92173 | I7: =I5+I6 -> 173.81007 | ... AL7: =AL5+AL6 -> 254.80899
A8: Новые платящие мастера: пробный период этого и прошлого месяца × конверсия × множитель каталога (строка 54) | B8: 0 | C8: =(B7*(1-Вводные!$B$60)+C7*Вводные!$B$60)*Вводные!$B$11*C54 -> 23.714386 | D8: =(C7*(1-Вводные!$B$60)+D7*Вводные!$B$60)*Вводные!$B$11*D54 -> 49.108707 | E8: =(D7*(1-Вводные!$B$60)+E7*Вводные!$B$60)*Вводные!$B$11*E54 -> 54.206769 | F8: =(E7*(1-Вводные!$B$60)+F7*Вводные!$B$60)*Вводные!$B$11*F54 -> 77.764107 | G8: =(F7*(1-Вводные!$B$60)+G7*Вводные!$B$60)*Вводные!$B$11*G54 -> 73.583702 | H8: =(G7*(1-Вводные!$B$60)+H7*Вводные!$B$60)*Вводные!$B$11*H54 -> 73.465707 | I8: =(H7*(1-Вводные!$B$60)+I7*Вводные!$B$60)*Вводные!$B$11*I54 -> 73.758975 | J8: =(I7*(1-Вводные!$B$60)+J7*Вводные!$B$60)*Вводные!$B$11*J54 -> 74.152152 | ... AL8: =(AK7*(1-Вводные!$B$60)+AL7*Вводные!$B$60)*Вводные!$B$11*AL54 -> 108.84168
A9: Ушли платящие мастера: база × базовый отток месяца (строка 56) × множитель каталога (строка 55) | B9: 0 | C9: =B10*C56*C55 -> 0 | D9: =C10*D56*D55 -> 1.1477973 | E9: =D10*E56*E55 -> 3.3636954 | F9: =E10*F56*F55 -> 3.4379756 | G9: =F10*G56*G55 -> 6.4944902 | H9: =G10*H56*H55 -> 9.1091691 | I9: =H10*I56*I55 -> 11.587445 | J9: =I10*J56*J55 -> 13.963226 | ... AL9: =AK10*AL56*AL55 -> 50.906474
A10: Платящих мастеров на конец месяца | B10: 0 | C10: =B10+C8-C9 -> 23.714386 | D10: =C10+D8-D9 -> 71.675295 | E10: =D10+E8-E9 -> 122.51837 | F10: =E10+F8-F9 -> 196.8445 | G10: =F10+G8-G9 -> 263.93371 | H10: =G10+H8-H9 -> 328.29025 | I10: =H10+I8-I9 -> 390.46178 | J10: =I10+J8-J9 -> 450.65071 | ... AL10: =AK10+AL8-AL9 -> 1996.3875
A11: Доля SAM на платной подписке | B11: 0 | C11: =IFERROR(C10/Вводные!$B$6,0) -> 0.00086865881 | D11: =IFERROR(D10/Вводные!$B$6,0) -> 0.0026254687 | E11: =IFERROR(E10/Вводные!$B$6,0) -> 0.0044878523 | F11: =IFERROR(F10/Вводные!$B$6,0) -> 0.0072104212 | G11: =IFERROR(G10/Вводные!$B$6,0) -> 0.0096679015 | H11: =IFERROR(H10/Вводные!$B$6,0) -> 0.012025284 | I11: =IFERROR(I10/Вводные!$B$6,0) -> 0.014302629 | J11: =IFERROR(J10/Вводные!$B$6,0) -> 0.016507352 | ... AL11: =IFERROR(AL10/Вводные!$B$6,0) -> 0.073127748
A13: Клиенты и записи
A14: Новые клиенты из рекламы (с учётом насыщения и роста клиентского бюджета, строка 50) | B14: =Маркетинг!B16*B45*B50 -> 0 | C14: =Маркетинг!C16*C45*C50 -> 0 | D14: =Маркетинг!D16*D45*D50 -> 0 | E14: =Маркетинг!E16*E45*E50 -> 541.71838 | F14: =Маркетинг!F16*F45*F50 -> 541.58619 | G14: =Маркетинг!G16*G45*G50 -> 541.36374 | H14: =Маркетинг!H16*H45*H50 -> 541.17614 | I14: =Маркетинг!I16*I45*I50 -> 541.00834 | ... AL14: =Маркетинг!AL16*AL45*AL50 -> 1812.1931
A15: Клиенты, которых перенесли новые мастера | B15: 0 | C15: =C8*Вводные!$B$14 -> 308.28701 | D15: =D8*Вводные!$B$14 -> 638.41319 | E15: =E8*Вводные!$B$14 -> 704.688 | F15: =F8*Вводные!$B$14 -> 1010.9334 | G15: =G8*Вводные!$B$14 -> 956.58812 | H15: =H8*Вводные!$B$14 -> 955.05419 | I15: =I8*Вводные!$B$14 -> 958.86667 | J15: =J8*Вводные!$B$14 -> 963.97798 | ... AL15: =AL8*Вводные!$B$14 -> 1414.9418
A16: Стали постоянными после первого визита | B16: 0 | C16: =B14*Вводные!$B$18 -> 0 | D16: =C14*Вводные!$B$18 -> 0 | E16: =D14*Вводные!$B$18 -> 0 | F16: =E14*Вводные!$B$18 -> 173.34988 | G16: =F14*Вводные!$B$18 -> 173.30758 | H16: =G14*Вводные!$B$18 -> 173.2364 | I16: =H14*Вводные!$B$18 -> 173.17636 | J16: =I14*Вводные!$B$18 -> 173.12267 | ... AL16: =AK14*Вводные!$B$18 -> 562.67555
A17: Ушли постоянные клиенты | B17: 0 | C17: =B18*Вводные!$B$19 -> 0 | D17: =C18*Вводные!$B$19 -> 31.961619 | E17: =D18*Вводные!$B$19 -> 94.835411 | F17: =E18*Вводные!$B$19 -> 158.0618 | G17: =F18*Вводные!$B$19 -> 264.45519 | H17: =G18*Вводные!$B$19 -> 354.17963 | I17: =H18*Вводные!$B$19 -> 434.43549 | J17: =I18*Вводные!$B$19 -> 506.75987 | ... AL17: =AK18*Вводные!$B$19 -> 1642.3448
A18: Постоянных клиентов на конец месяца | B18: 0 | C18: =B18+C15+C16-C17 -> 308.28701 | D18: =C18+D15+D16-D17 -> 914.73858 | E18: =D18+E15+E16-E17 -> 1524.5912 | F18: =E18+F15+F16-F17 -> 2550.8126 | G18: =F18+G15+G16-G17 -> 3416.2531 | H18: =G18+H15+H16-H17 -> 4190.3641 | I18: =H18+I15+I16-I17 -> 4887.9716 | J18: =I18+J15+J16-J17 -> 5518.3124 | ... AL18: =AK18+AL15+AL16-AL17 -> 16176.572
A19: Записей через платформу | B19: =B14 -> 0 | C19: =C14+C18*Вводные!$B$8/12 -> 359.66818 | D19: =D14+D18*Вводные!$B$8/12 -> 1067.195 | E19: =E14+E18*Вводные!$B$8/12 -> 2320.4081 | F19: =F14+F18*Вводные!$B$8/12 -> 3517.5343 | G19: =G14+G18*Вводные!$B$8/12 -> 4526.9924 | H19: =H14+H18*Вводные!$B$8/12 -> 5429.9343 | I19: =I14+I18*Вводные!$B$8/12 -> 6243.6419 | J19: =J14+J18*Вводные!$B$8/12 -> 6978.8883 | ... AL19: =AL14+AL18*Вводные!$B$8/12 -> 20684.86
A20: Записей на одного платящего мастера | B20: 0 | C20: =IFERROR(C19/C10,0) -> 15.166667 | D20: =IFERROR(D19/D10,0) -> 14.889301 | E20: =IFERROR(E19/E10,0) -> 18.939267 | F20: =IFERROR(F19/F10,0) -> 17.869609 | G20: =IFERROR(G19/G10,0) -> 17.152005 | H20: =IFERROR(H19/H10,0) -> 16.540041 | I20: =IFERROR(I19/I10,0) -> 15.990405 | J20: =IFERROR(J19/J10,0) -> 15.486247 | ... AL20: =IFERROR(AL19/AL10,0) -> 10.361145
A21: GMV: оборот записей через платформу (деньги мастеров, не выручка Камертона) | B21: =B19*Вводные!$B$7 -> 0 | C21: =C19*Вводные!$B$7 -> 1147341.5 | D21: =D19*Вводные!$B$7 -> 3404352.1 | E21: =E19*Вводные!$B$7 -> 7402101.8 | F21: =F19*Вводные!$B$7 -> 11220934 | G21: =G19*Вводные!$B$7 -> 14441106 | H21: =H19*Вводные!$B$7 -> 17321490 | I21: =I19*Вводные!$B$7 -> 19917218 | ... AL21: =AL19*Вводные!$B$7 -> 65984704
A23: Выручка
A24: Выручка от подписок | B24: 0 | C24: =C10*Вводные!$B$21 -> 23477.242 | D24: =D10*Вводные!$B$21 -> 70958.542 | E24: =E10*Вводные!$B$21 -> 121293.19 | F24: =F10*Вводные!$B$21 -> 194876.06 | G24: =G10*Вводные!$B$21 -> 261294.37 | H24: =H10*Вводные!$B$21 -> 325007.35 | I24: =I10*Вводные!$B$21 -> 386557.16 | J24: =J10*Вводные!$B$21 -> 446144.2 | ... AL24: =AL10*Вводные!$B$21 -> 1976423.7
A25: Выручка от продвижения (доля покупающих растёт с базой, строка 57) | B25: 0 | C25: =IF(C$2>=Вводные!$B$24,C10*C57*Вводные!$B$22,0) -> 0 | D25: =IF(D$2>=Вводные!$B$24,D10*D57*Вводные!$B$22,0) -> 0 | E25: =IF(E$2>=Вводные!$B$24,E10*E57*Вводные!$B$22,0) -> 0 | F25: =IF(F$2>=Вводные!$B$24,F10*F57*Вводные!$B$22,0) -> 23862.471 | G25: =IF(G$2>=Вводные!$B$24,G10*G57*Вводные!$B$22,0) -> 40322.887 | H25: =IF(H$2>=Вводные!$B$24,H10*H57*Вводные!$B$22,0) -> 58866.842 | I25: =IF(I$2>=Вводные!$B$24,I10*I57*Вводные!$B$22,0) -> 78834.777 | J25: =IF(J$2>=Вводные!$B$24,J10*J57*Вводные!$B$22,0) -> 99706.364 | ... AL25: =IF(AL$2>=Вводные!$B$24,AL10*AL57*Вводные!$B$22,0) -> 729935.09
A26: Выручка всего без НДС | B26: =SUM(B24:B25)-B27 -> 0 | C26: =SUM(C24:C25)-C27 -> 23477.242 | D26: =SUM(D24:D25)-D27 -> 70958.542 | E26: =SUM(E24:E25)-E27 -> 121293.19 | F26: =SUM(F24:F25)-F27 -> 218738.53 | G26: =SUM(G24:G25)-G27 -> 301617.26 | H26: =SUM(H24:H25)-H27 -> 383874.19 | I26: =SUM(I24:I25)-I27 -> 465391.94 | ... AL26: =SUM(AL24:AL25)-AL27 -> 2577484.5
A27: НДС на УСН в цене подписки и продвижения (с месяца после превышения порога) | B27: =(B24+B25)*B62*Вводные!$B$77/(1+Вводные!$B$77) -> 0 | C27: =(C24+C25)*C62*Вводные!$B$77/(1+Вводные!$B$77) -> 0 | D27: =(D24+D25)*D62*Вводные!$B$77/(1+Вводные!$B$77) -> 0 | E27: =(E24+E25)*E62*Вводные!$B$77/(1+Вводные!$B$77) -> 0 | F27: =(F24+F25)*F62*Вводные!$B$77/(1+Вводные!$B$77) -> 0 | G27: =(G24+G25)*G62*Вводные!$B$77/(1+Вводные!$B$77) -> 0 | H27: =(H24+H25)*H62*Вводные!$B$77/(1+Вводные!$B$77) -> 0 | I27: =(I24+I25)*I62*Вводные!$B$77/(1+Вводные!$B$77) -> 0 | ... AL27: =(AL24+AL25)*AL62*Вводные!$B$77/(1+Вводные!$B$77) -> 128874.23
A28: Расходы
A29: OPEX | B29: =IF(B$2>=Вводные!$B$30,OPEX!$D$7,0) -> 0 | C29: =IF(C$2>=Вводные!$B$30,OPEX!$D$7,0) -> 375122.33 | D29: =IF(D$2>=Вводные!$B$30,OPEX!$D$7,0) -> 375122.33 | E29: =IF(E$2>=Вводные!$B$30,OPEX!$D$7,0) -> 375122.33 | F29: =IF(F$2>=Вводные!$B$30,OPEX!$D$7,0) -> 375122.33 | G29: =IF(G$2>=Вводные!$B$30,OPEX!$D$7,0) -> 375122.33 | H29: =IF(H$2>=Вводные!$B$30,OPEX!$D$7,0) -> 375122.33 | I29: =IF(I$2>=Вводные!$B$30,OPEX!$D$7,0) -> 375122.33 | ... AL29: =IF(AL$2>=Вводные!$B$30,OPEX!$D$7,0) -> 375122.33
A30: Маркетинг (клиентские каналы × рост клиентского бюджета, строка 50) | B30: =Маркетинг!B15+Маркетинг!B17*B50 -> 0 | C30: =Маркетинг!C15+Маркетинг!C17*C50 -> 135000 | D30: =Маркетинг!D15+Маркетинг!D17*D50 -> 190000 | E30: =Маркетинг!E15+Маркетинг!E17*E50 -> 247500 | F30: =Маркетинг!F15+Маркетинг!F17*F50 -> 247500 | G30: =Маркетинг!G15+Маркетинг!G17*G50 -> 247500 | H30: =Маркетинг!H15+Маркетинг!H17*H50 -> 247500 | I30: =Маркетинг!I15+Маркетинг!I17*I50 -> 247500 | ... AL30: =Маркетинг!AL15+Маркетинг!AL17*AL50 -> 454469.75
A31: Разработка | B31: =Разработка!$I$10 -> 3085641 | C31: =0 -> 0 | D31: =0 -> 0 | E31: =0 -> 0 | F31: =0 -> 0 | G31: =0 -> 0 | H31: =0 -> 0 | I31: =0 -> 0 | J31: =0 -> 0 | ... AL31: =0 -> 0
A32: Переменные расходы на обслуживание: проверка мастеров, напоминания, эквайринг | B32: =B7*OPEX!$C$10+B19*OPEX!$C$11+B26*Вводные!$B$26 -> 0 | C32: =C7*OPEX!$C$10+C19*OPEX!$C$11+C26*Вводные!$B$26 -> 25771.188 | D32: =D7*OPEX!$C$10+D19*OPEX!$C$11+D26*Вводные!$B$26 -> 33413.86 | E32: =E7*OPEX!$C$10+E19*OPEX!$C$11+E26*Вводные!$B$26 -> 38128.524 | F32: =F7*OPEX!$C$10+F19*OPEX!$C$11+F26*Вводные!$B$26 -> 44817.626 | G32: =G7*OPEX!$C$10+G19*OPEX!$C$11+G26*Вводные!$B$26 -> 51098.116 | H32: =H7*OPEX!$C$10+H19*OPEX!$C$11+H26*Вводные!$B$26 -> 57005.956 | I32: =I7*OPEX!$C$10+I19*OPEX!$C$11+I26*Вводные!$B$26 -> 62658.913 | ... AL32: =AL7*OPEX!$C$10+AL19*OPEX!$C$11+AL26*Вводные!$B$26 -> 186622.57
A33: Расходы до налога, итого | B33: =SUM(B29:B32) -> 3085641 | C33: =SUM(C29:C32) -> 535893.52 | D33: =SUM(D29:D32) -> 598536.19 | E33: =SUM(E29:E32) -> 660750.86 | F33: =SUM(F29:F32) -> 667439.96 | G33: =SUM(G29:G32) -> 673720.45 | H33: =SUM(H29:H32) -> 679628.29 | I33: =SUM(I29:I32) -> 685281.25 | ... AL33: =SUM(AL29:AL32) -> 1016214.7
A35: Прибыль до налога | B35: =B26-B33 -> -3085641 | C35: =C26-C33 -> -512416.28 | D35: =D26-D33 -> -527577.65 | E35: =E26-E33 -> -539457.67 | F35: =F26-F33 -> -448701.43 | G35: =G26-G33 -> -372103.19 | H35: =H26-H33 -> -295754.1 | I35: =I26-I33 -> -219889.31 | ... AL35: =AL26-AL33 -> 1561269.9
A36: Прибыль до налога нарастающим итогом (для переноса убытков) | B36: =B35 -> -3085641 | C36: =B36+C35 -> -3598057.3 | D36: =C36+D35 -> -4125634.9 | E36: =D36+E35 -> -4665092.6 | F36: =E36+F35 -> -5113794 | G36: =F36+G35 -> -5485897.2 | H36: =G36+H35 -> -5781651.3 | I36: =H36+I35 -> -6001540.6 | J36: =I36+J35 -> -6146386 | ... AL36: =AK36+AL35 -> 14996002
A37: Налог УСН (годовой налог, распределён поровну по месяцам года) | B37: =0 -> 0 | C37: =MAX(Вводные!$B$28*SUM($B$26:$N$26),Вводные!$B$27*MAX(0,$N$36))/12 -> 4239.5131 | D37: =MAX(Вводные!$B$28*SUM($B$26:$N$26),Вводные!$B$27*MAX(0,$N$36))/12 -> 4239.5131 | E37: =MAX(Вводные!$B$28*SUM($B$26:$N$26),Вводные!$B$27*MAX(0,$N$36))/12 -> 4239.5131 | F37: =MAX(Вводные!$B$28*SUM($B$26:$N$26),Вводные!$B$27*MAX(0,$N$36))/12 -> 4239.5131 | G37: =MAX(Вводные!$B$28*SUM($B$26:$N$26),Вводные!$B$27*MAX(0,$N$36))/12 -> 4239.5131 | H37: =MAX(Вводные!$B$28*SUM($B$26:$N$26),Вводные!$B$27*MAX(0,$N$36))/12 -> 4239.5131 | I37: =MAX(Вводные!$B$28*SUM($B$26:$N$26),Вводные!$B$27*MAX(0,$N$36))/12 -> 4239.5131 | J37: =MAX(Вводные!$B$28*SUM($B$26:$N$26),Вводные!$B$27*MAX(0,$N$36))/12 -> 4239.5131 | ... N37: =MAX(Вводные!$B$28*SUM($B$26:$N$26),Вводные!$B$27*MAX(0,$N$36))/12 -> 4239.5131 | O37: =MAX(Вводные!$B$28*SUM($O$26:$Z$26),Вводные!$B$27*(MAX(0,$Z$36)-MAX(0,$N$36)))/12 -> 13338.761 | P37: =MAX(Вводные!$B$28*SUM($O$26:$Z$26),Вводные!$B$27*(MAX(0,$Z$36)-MAX(0,$N$36)))/12 -> 13338.761 | Q37: =MAX(Вводные!$B$28*SUM($O$26:$Z$26),Вводные!$B$27*(MAX(0,$Z$36)-MAX(0,$N$36)))/12 -> 13338.761 | R37: =MAX(Вводные!$B$28*SUM($O$26:$Z$26),Вводные!$B$27*(MAX(0,$Z$36)-MAX(0,$N$36)))/12 -> 13338.761 | S37: =MAX(Вводные!$B$28*SUM($O$26:$Z$26),Вводные!$B$27*(MAX(0,$Z$36)-MAX(0,$N$36)))/12 -> 13338.761 | T37: =MAX(Вводные!$B$28*SUM($O$26:$Z$26),Вводные!$B$27*(MAX(0,$Z$36)-MAX(0,$N$36)))/12 -> 13338.761 | U37: =MAX(Вводные!$B$28*SUM($O$26:$Z$26),Вводные!$B$27*(MAX(0,$Z$36)-MAX(0,$N$36)))/12 -> 13338.761 | V37: =MAX(Вводные!$B$28*SUM($O$26:$Z$26),Вводные!$B$27*(MAX(0,$Z$36)-MAX(0,$N$36)))/12 -> 13338.761 | ... Z37: =MAX(Вводные!$B$28*SUM($O$26:$Z$26),Вводные!$B$27*(MAX(0,$Z$36)-MAX(0,$N$36)))/12 -> 13338.761 | AA37: =MAX(Вводные!$B$28*SUM($AA$26:$AL$26),Вводные!$B$27*(MAX(0,$AL$36)-MAX(0,$Z$36)))/12 -> 182072.63 | AB37: =MAX(Вводные!$B$28*SUM($AA$26:$AL$26),Вводные!$B$27*(MAX(0,$AL$36)-MAX(0,$Z$36)))/12 -> 182072.63 | AC37: =MAX(Вводные!$B$28*SUM($AA$26:$AL$26),Вводные!$B$27*(MAX(0,$AL$36)-MAX(0,$Z$36)))/12 -> 182072.63 | AD37: =MAX(Вводные!$B$28*SUM($AA$26:$AL$26),Вводные!$B$27*(MAX(0,$AL$36)-MAX(0,$Z$36)))/12 -> 182072.63 | AE37: =MAX(Вводные!$B$28*SUM($AA$26:$AL$26),Вводные!$B$27*(MAX(0,$AL$36)-MAX(0,$Z$36)))/12 -> 182072.63 | AF37: =MAX(Вводные!$B$28*SUM($AA$26:$AL$26),Вводные!$B$27*(MAX(0,$AL$36)-MAX(0,$Z$36)))/12 -> 182072.63 | AG37: =MAX(Вводные!$B$28*SUM($AA$26:$AL$26),Вводные!$B$27*(MAX(0,$AL$36)-MAX(0,$Z$36)))/12 -> 182072.63 | AH37: =MAX(Вводные!$B$28*SUM($AA$26:$AL$26),Вводные!$B$27*(MAX(0,$AL$36)-MAX(0,$Z$36)))/12 -> 182072.63 | ... AL37: =MAX(Вводные!$B$28*SUM($AA$26:$AL$26),Вводные!$B$27*(MAX(0,$AL$36)-MAX(0,$Z$36)))/12 -> 182072.63
A38: Расходы с налогом, итого | B38: =B33+B37 -> 3085641 | C38: =C33+C37 -> 540133.03 | D38: =D33+D37 -> 602775.71 | E38: =E33+E37 -> 664990.37 | F38: =F33+F37 -> 671679.47 | G38: =G33+G37 -> 677959.96 | H38: =H33+H37 -> 683867.8 | I38: =I33+I37 -> 689520.76 | ... AL38: =AL33+AL37 -> 1198287.3
A40: Чистая прибыль | B40: =B35-B37 -> -3085641 | C40: =C35-C37 -> -516655.79 | D40: =D35-D37 -> -531817.16 | E40: =E35-E37 -> -543697.19 | F40: =F35-F37 -> -452940.95 | G40: =G35-G37 -> -376342.7 | H40: =H35-H37 -> -299993.61 | I40: =I35-I37 -> -224128.82 | ... AL40: =AL35-AL37 -> 1379197.2
A41: Накопленная прибыль | B41: =B40 -> -3085641 | C41: =B41+C40 -> -3602296.8 | D41: =C41+D40 -> -4134114 | E41: =D41+E40 -> -4677811.1 | F41: =E41+F40 -> -5130752.1 | G41: =F41+G40 -> -5507094.8 | H41: =G41+H40 -> -5807088.4 | I41: =H41+I40 -> -6031217.2 | J41: =I41+J40 -> -6180302.1 | ... AL41: =AK41+AL40 -> 12600191
A43: Насыщение рынка (модель Басса)
A44: Коэффициент притока мастеров: 1 − платящие мастера / ёмкость рынка | B44: 1 | C44: =MAX(0,1-B10/Вводные!$B$51) -> 1 | D44: =MAX(0,1-C10/Вводные!$B$51) -> 0.99913134 | E44: =MAX(0,1-D10/Вводные!$B$51) -> 0.99737453 | F44: =MAX(0,1-E10/Вводные!$B$51) -> 0.99551215 | G44: =MAX(0,1-F10/Вводные!$B$51) -> 0.99278958 | H44: =MAX(0,1-G10/Вводные!$B$51) -> 0.9903321 | I44: =MAX(0,1-H10/Вводные!$B$51) -> 0.98797472 | J44: =MAX(0,1-I10/Вводные!$B$51) -> 0.98569737 | ... AL44: =MAX(0,1-AK10/Вводные!$B$51) -> 0.92899442
A45: Коэффициент притока клиентов: 1 − постоянные клиенты / ёмкость аудитории | B45: 1 | C45: =MAX(0,1-B18/Вводные!$B$52) -> 1 | D45: =MAX(0,1-C18/Вводные!$B$52) -> 0.99987669 | E45: =MAX(0,1-D18/Вводные!$B$52) -> 0.9996341 | F45: =MAX(0,1-E18/Вводные!$B$52) -> 0.99939016 | G45: =MAX(0,1-F18/Вводные!$B$52) -> 0.99897967 | H45: =MAX(0,1-G18/Вводные!$B$52) -> 0.9986335 | I45: =MAX(0,1-H18/Вводные!$B$52) -> 0.99832385 | J45: =MAX(0,1-I18/Вводные!$B$52) -> 0.99804481 | ... AL45: =MAX(0,1-AK18/Вводные!$B$52) -> 0.99366348
A46: Стоимость регистрации мастера с учётом насыщения и холодного старта, ₽ | B46: =IFERROR(Маркетинг!B15/B5,0) -> 0 | C46: =IFERROR(Маркетинг!C15/C5,0) -> 1423.295 | D46: =IFERROR(Маркетинг!D15/D5,0) -> 1618.4561 | E46: =IFERROR(Маркетинг!E15/E5,0) -> 1324.9907 | F46: =IFERROR(Маркетинг!F15/F5,0) -> 1288.673 | G46: =IFERROR(Маркетинг!G15/G5,0) -> 1242.0024 | H46: =IFERROR(Маркетинг!H15/H5,0) -> 1205.6531 | I46: =IFERROR(Маркетинг!I15/I5,0) -> 1175.2867 | ... AL46: =IFERROR(Маркетинг!AL15/AL5,0) -> 1002.8099
...

Sheet Функции
A1: Функция | B1: Для кого | C1: Этап | D1: Экранов / вариантов | E1: Сложность | F1: UX часы | G1: Frontend часы | H1: Backend часы | I1: QA часы | J1: Где в прототипе / обоснование
A2: Поиск по совпадению: метки, фильтры (услуга, метро, место, цена), сортировка | B2: клиент | C2: MVP | D2: 3 | E2: 1 | F2: =D2*E2*10 -> 30 | G2: =D2*E2*18 -> 54 | H2: =D2*E2*12 -> 36 | I2: =D2*E2*8 -> 24 | J2: Прототип: belyaevartemg-sudo.github.io/ritm — экран «Найти мастера»: выдача, панель фильтров, пустая выдача. Сложнее остальных: логика совпадения по меткам
A3: Карточка мастера в каталоге: ближайшее окно, метки, «Проверенный мастер» | B3: клиент | C3: MVP | D3: 2 | E3: 0.7 | F3: =D3*E3*10 -> 14 | G3: =D3*E3*18 -> 25.2 | H3: =D3*E3*12 -> 16.8 | I3: =D3*E3*8 -> 11.2 | J3: Прототип: belyaevartemg-sudo.github.io/ritm — карточка в выдаче, состояние «нет окон»
A4: Профиль мастера для клиента: работы, услуги и цены, где принимает, отзывы | B4: клиент | C4: MVP | D4: 4 | E4: 0.8 | F4: =D4*E4*10 -> 32 | G4: =D4*E4*18 -> 57.6 | H4: =D4*E4*12 -> 38.4 | I4: =D4*E4*8 -> 25.6 | J4: Прототип: belyaevartemg-sudo.github.io/ritm — профиль: блоки «Работы», «Услуги и цены», «Где принимает», «Отзывы»
A5: Анкета мастера: метки манеры, место, адрес, о себе, фото работ | B5: мастер | C5: MVP | D5: 4 | E5: 0.8 | F5: =D5*E5*10 -> 32 | G5: =D5*E5*18 -> 57.6 | H5: =D5*E5*12 -> 38.4 | I5: =D5*E5*8 -> 25.6 | J5: Прототип: belyaevartemg-sudo.github.io/ritm — кабинет мастера, вкладка «Профиль и услуги»: метки, место, услуги, фото
A6: Онлайн-запись: услуга → день → окно → подтверждение | B6: клиент | C6: MVP | D6: 3 | E6: 1.4 | F6: =D6*E6*10 -> 42 | G6: =D6*E6*18 -> 75.6 | H6: =D6*E6*12 -> 50.4 | I6: =D6*E6*8 -> 33.6 | J6: Прототип: belyaevartemg-sudo.github.io/ritm — «Свободные окна на неделю», выбор времени, подтверждение. Нужна защита от двойной записи
A7: Расписание мастера: окна на неделю, открыть / закрыть | B7: мастер | C7: MVP | D7: 2 | E7: 0.9 | F7: =D7*E7*10 -> 18 | G7: =D7*E7*18 -> 32.4 | H7: =D7*E7*12 -> 21.6 | I7: =D7*E7*8 -> 14.4 | J7: Прототип: belyaevartemg-sudo.github.io/ritm — вкладка «Расписание»: окна, «Открыть все будни 11–19», «Закрыть все свободные»
A8: Напоминания: push, Telegram, SMS; «Приду» / «Перенести» | B8: клиент/мастер | C8: MVP | D8: 2 | E8: 1 | F8: =D8*E8*10 -> 20 | G8: =D8*E8*18 -> 36 | H8: =D8*E8*12 -> 24 | I8: =D8*E8*8 -> 16 | J8: Прототип: belyaevartemg-sudo.github.io/ritm — «Как выглядит push», кнопки «Приду» и «Перенести». Интеграции с push, Telegram-ботом и SMS-агрегатором
A9: Отзыв после визита: звёзды и отметки «что совпало» | B9: клиент | C9: MVP | D9: 2 | E9: 1 | F9: =D9*E9*10 -> 20 | G9: =D9*E9*18 -> 36 | H9: =D9*E9*12 -> 24 | I9: =D9*E9*8 -> 16 | J9: Прототип: belyaevartemg-sudo.github.io/ritm — форма «Оставить отзыв», «Ваши отметки». Отзыв — только после записи через сервис
A10: Модерация: фото, документы, отзывы; «Проверенный мастер» | B10: команда | C10: MVP | D10: 3 | E10: 1 | F10: =D10*E10*10 -> 30 | G10: =D10*E10*18 -> 54 | H10: =D10*E10*12 -> 36 | I10: =D10*E10*8 -> 24 | J10: В прототипе только статус «Проверенный мастер» и тексты про модерацию. Нужна админка: очередь профилей, отзывов и фото
A11: Регистрация, роли «клиент / мастер», ссылка на запись для своих клиентов | B11: мастер/клиент | C11: MVP | D11: 3 | E11: 1 | F11: =D11*E11*10 -> 30 | G11: =D11*E11*18 -> 54 | H11: =D11*E11*12 -> 36 | I11: =D11*E11*8 -> 24 | J11: Прототип: belyaevartemg-sudo.github.io/ritm — переключатель «Клиент / Мастер», блок «Ссылка на запись». Вход по телефону — в прототипе нет
A12: Подписка: 14 дней бесплатно, рекуррентная оплата | B12: мастер | C12: MVP | D12: 2 | E12: 0.5 | F12: =D12*E12*10 -> 10 | G12: =D12*E12*18 -> 18 | H12: =D12*E12*12 -> 12 | I12: =D12*E12*8 -> 8 | J12: Прототип: belyaevartemg-sudo.github.io/ritm — вкладка «Тариф». Оплаты в прототипе нет: нужна интеграция с эквайрингом
A13: Мои записи: перенос, отмена, «записаться снова» | B13: клиент | C13: MVP | D13: 2 | E13: 0.6 | F13: =D13*E13*10 -> 12 | G13: =D13*E13*18 -> 21.6 | H13: =D13*E13*12 -> 14.4 | I13: =D13*E13*8 -> 9.6 | J13: Прототип: belyaevartemg-sudo.github.io/ritm — вкладка «Мои записи»: перенос, отмена, «Записаться снова»
A14: Чаты и платное продвижение у станции метро | B14: клиент/мастер | C14: После запуска | D14: 4 | E14: 0.5 | F14: =D14*E14*10 -> 20 | G14: =D14*E14*18 -> 36 | H14: =D14*E14*12 -> 24 | I14: =D14*E14*8 -> 16 | J14: Прототип: belyaevartemg-sudo.github.io/ritm — вкладки «Чаты» и «Тариф → Продвижение». В MVP чаты заменяет кнопка «Написать в Telegram», продвижение запускаем позже — оплата из OPEX
A15: Итого MVP (строки с этапом «MVP») | D15: =SUMIF($C$2:$C$14,"MVP",D2:D14) -> 32 | E15: =SUMIF($C$2:$C$14,"MVP",E2:E14) -> 10.7 | F15: =SUMIF($C$2:$C$14,"MVP",F2:F14) -> 290 | G15: =SUMIF($C$2:$C$14,"MVP",G2:G14) -> 522 | H15: =SUMIF($C$2:$C$14,"MVP",H2:H14) -> 348 | I15: =SUMIF($C$2:$C$14,"MVP",I2:I14) -> 232
A17: Часы = экраны × сложность × часы роли на экран (UX 10, Frontend 18, Backend 12, QA 8) — [допущение] модели, сверено с рынком на листе «Разработка». В CAPEX попадают только функции с этапом «MVP»; «После запуска» оплачивается из OPEX (техподдержка и доработки). Экраны посчитаны по прототипу. Сложность 1,0 — простая форма, 1,5 — своя логика или внешняя интеграция [допущение].

Sheet Разработка
A1: Роль | B1: ЗП/мес | C1: Ставка ₽/час | D1: Базовые часы | E1: Часы от функций | F1: Итого часов (с учётом ИИ) | G1: ФОТ | H1: Страховые взносы | I1: Итого | J1: Источник / обоснование
A2: Product Manager | B2: 260000 | C2: =B2/160 -> 1625 | D2: 240 | E2: 0 | F2: =D2+E2 -> 240 | G2: =C2*F2 -> 390000 | H2: =G2*Вводные!$B$31 -> 117000 | I2: =G2+H2 -> 507000 | J2: ЗП: медиана «менеджеры в IT», Москва — 260 000 ₽ (Хабр Карьера, 1-е полугодие 2026). Часы [допущение]: половина ставки на 3 месяца MVP
A3: UX/UI Designer | B3: 120000 | C3: =B3/160 -> 750 | D3: 0 | E3: =Функции!F15 -> 290 | F3: =(D3+E3)*(1-Вводные!$B$34) -> 174 | G3: =C3*F3 -> 130500 | H3: =G3*Вводные!$B$31 -> 39150 | I3: =G3+H3 -> 169650 | J3: ЗП: средняя UX/UI в Москве ≈120 000 ₽ (quick-offer.ru, 26.03.2026). Базовых часов нет: дизайн-система и айдентика уже готовы в прототипе
A4: Frontend Developer | B4: 270000 | C4: =B4/160 -> 1687.5 | D4: 80 | E4: =Функции!G15 -> 522 | F4: =(D4+E4)*(1-Вводные!$B$34) -> 361.2 | G4: =C4*F4 -> 609525 | H4: =G4*Вводные!$B$31 -> 182857.5 | I4: =G4+H4 -> 792382.5 | J4: ЗП: медиана разработчиков, Москва — 270 000 ₽ (Хабр Карьера, 28.08.2026). Базовые часы [допущение]: каркас приложения, навигация, вход
A5: Backend Developer | B5: 278000 | C5: =B5/160 -> 1737.5 | D5: 240 | E5: =Функции!H15 -> 348 | F5: =(D5+E5)*(1-Вводные!$B$34) -> 352.8 | G5: =C5*F5 -> 612990 | H5: =G5*Вводные!$B$31 -> 183897 | I5: =G5+H5 -> 796887 | J5: ЗП: медиана бэкенда, Москва — 278 000 ₽ (Хабр Карьера, 1-е полугодие 2026). Базовые часы [допущение]: архитектура, база данных, API, авторизация, каркас админки
A6: QA Engineer | B6: 163000 | C6: =B6/160 -> 1018.75 | D6: 40 | E6: =Функции!I15 -> 232 | F6: =(D6+E6)*(1-Вводные!$B$34) -> 163.2 | G6: =C6*F6 -> 166260 | H6: =G6*Вводные!$B$31 -> 49878 | I6: =G6+H6 -> 216138 | J6: ЗП: медиана тестировщиков — 163 000 ₽, по России (Хабр Карьера, 1-е полугодие 2026). Базовые часы [допущение]: тест-план и регресс перед релизом
A7: DevOps Engineer | B7: 229000 | C7: =B7/160 -> 1431.25 | D7: 80 | E7: 0 | F7: =(D7+E7)*(1-Вводные!$B$34) -> 48 | G7: =C7*F7 -> 68700 | H7: =G7*Вводные!$B$31 -> 20610 | I7: =G7+H7 -> 89310 | J7: ЗП: прокси — медиана администраторов, Москва — 229 000 ₽ (Хабр Карьера, 1-е полугодие 2026; по DevOps отдельной цифры нет). Часы [допущение]: облако, CI/CD, мониторинг
A8: Итого разработка без резерва | F8: =SUM(F2:F7) -> 1339.2 | G8: =SUM(G2:G7) -> 1977975 | H8: =SUM(H2:H7) -> 593392.5 | I8: =SUM(I2:I7) -> 2571367.5
A9: Резерв на непредвиденные работы | F9: =F8*Вводные!$B$32 -> 267.84 | I9: =I8*Вводные!$B$32 -> 514273.5
A10: Итого CAPEX / разработка MVP | F10: =F8+F9 -> 1607.04 | I10: =I8+I9 -> 3085641
A12: Итого часов = (базовые + часы от функций) × (1 − сокращение за счёт ИИ, лист «Вводные»); для менеджера продукта без сокращения. 160 рабочих часов в месяц = 8 часов × 20 рабочих дней. Резерв 20% — по рекомендации PMI. Разработка MVP оплачивается один раз в месяц 0, дальше доработки идут через OPEX.
A14: Сверка с рынком
A15: Итого часов на MVP (с резервом) | F15: =F10 -> 1607.04
A16: Ёмкость команды из 4 человек за 3 месяца, часов | F16: 1920 | J16: Purrweb, 2026: MVP — 2–3 месяца, команда около 4 человек (дизайнер, 1–2 разработчика, QA, PM)
A17: Стоимость MVP у агентства со сложной логикой и интеграциями, млн ₽ | F17: 3–6 | J17: Purrweb, 2026: MVP 1,5–6 млн ₽; со сложной логикой или интеграциями — 3–6 млн ₽. Наша оценка включает страховые взносы 30% и резерв 20%
A18: Наша оценка CAPEX, млн ₽ | F18: =I10/1000000 -> 3.085641

Sheet OPEX
A1: Категория | B1: Формула/допущение | C1: Стоимость в год | D1: Стоимость в месяц
A2: Разработчик: поддержка и доработки | B2: Медианная зарплата разработчика × ставка (Вводные, строка 33) × (1 + взносы) | C2: =Вводные!$B$33*Разработка!$B$4*(1+Вводные!$B$31)*12 -> 1053000 | D2: =C2/12 -> 87750
A3: Хостинг, хранение фото, аналитика | B3: Облачные серверы, хранилище фото, аналитика (расшифровка ниже) | C3: =SUM(E14:E16)*12 -> 204948 | D3: =C3/12 -> 17079
A4: Команда после запуска | B4: Менеджер по привлечению мастеров, основатели (расшифровка ниже) | C4: =SUM(E17:E18)*12 -> 1560000 | D4: =C4/12 -> 130000
A5: Поддержка и модерация мастеров | B5: Ответы мастерам и клиентам, модерация профилей и отзывов (расшифровка ниже) | C5: =E19*12 -> 1528800 | D5: =C5/12 -> 127400
A6: Бухгалтерия и юрист | B6: Бухгалтерия на аутсорсе, юрист (расшифровка ниже) | C6: =SUM(E20:E21)*12 -> 154720 | D6: =C6/12 -> 12893.333
A7: Итого OPEX | C7: =SUM(C2:C6) -> 4501468 | D7: =SUM(D2:D6) -> 375122.33
A9: Обслуживание | C9: Стоимость на единицу | D9: За что
A10: Проверка и подключение нового мастера | B10: Модерация анкеты + SMS с кодом подтверждения (расшифровка ниже) | C10: =C24/60*C25+C26 -> 203.0625 | D10: новый мастер
A11: Напоминание о записи (SMS; push и Telegram бесплатно) | B11: Цена SMS × доля напоминаний по SMS (расшифровка ниже) | C11: =C26*C27 -> 1.2 | D11: запись
A13: Расшифровка постоянных расходов | B13: Источник / обоснование | C13: Цена в месяц, ₽ | D13: Кол-во | E13: Итого в месяц, ₽
A14: Облачный сервер 2 vCPU / 4 ГБ: приложение, база данных, тестовый стенд | B14: Timeweb Cloud, тариф MSK Ultra 50 — 5 480 ₽/мес | C14: 5480 | D14: 3 | E14: =C14*D14 -> 16440
A15: Хранилище фото работ (S3), безлимитный объём | B15: Timeweb Cloud S3 — 639 ₽/мес | C15: 639 | D15: 1 | E15: =C15*D15 -> 639
A16: Веб-аналитика (Яндекс Метрика) | B16: Бесплатный сервис | C16: 0 | D16: 1 | E16: =C16*D16 -> 0
A17: Менеджер по привлечению мастеров (с взносами) | B17: hh.ru, вакансии «Менеджер по привлечению партнёров», 2026: от 100 000 ₽ + премия за клиента | C17: 100000 | D17: 1 | E17: =C17*D17*(1+Вводные!$B$31) -> 130000
A18: Основатели (с взносами) | B18: [решение команды] Основатели (6 человек) не получают зарплату | C18: 0 | D18: 6 | E18: =C18*D18*(1+Вводные!$B$31) -> 0
A19: Специалист поддержки и модерации (с взносами) | B19: Хабр Карьера, 1-е полугодие 2026: медиана техподдержки 98 000 ₽ | C19: 98000 | D19: 1 | E19: =C19*D19*(1+Вводные!$B$31) -> 127400
A20: Бухгалтерия на аутсорсе (ООО на УСН с сотрудниками) | B20: Сравни: полный аутсорсинг бухгалтерии — от 12 200 ₽/мес (Фингуру) | C20: 12200 | D20: 1 | E20: =C20*D20 -> 12200
A21: Юрист: оферта для мастеров, политика ПДн, уведомление в Роскомнадзор | B21: fl.ru, 2026: политика ПДн — 3 120 ₽, публичная оферта — 3 120 ₽, уведомление РКН — 2 080 ₽. Итого 8 320 ₽ разово; делим на 12 мес. — документы обновляем раз в год | C21: =(3120+3120+2080)/12 -> 693.33333 | D21: 1 | E21: =C21*D21 -> 693.33333
A23: Расшифровка обслуживания | B23: Источник / обоснование | C23: Значение | D23: Ед.
A24: Время модерации одного нового мастера | B24: [допущение] Проверка фото, документа и анкеты | C24: 15 | D24: мин
A25: Стоимость часа специалиста поддержки с взносами | B25: Расчёт: зарплата × (1 + взносы) / 160 часов | C25: =C19*(1+Вводные!$B$31)/160 -> 796.25 | D25: ₽/час
A26: Цена одного SMS | B26: tproger, 2026: 2,5–6 ₽ за SMS у агрегаторов, берём середину | C26: 4 | D26: ₽
A27: Доля напоминаний по SMS (остальным — push или Telegram-бот бесплатно) | B27: [допущение] | C27: 0.3 | D27: %

Sheet Маркетинг
A1: Канал | B1: Что входит | C1: Разовый бюджет | D1: Месячный бюджет | E1: Охват/мес (показы или просмотры) | F1: Конверсия | G1: Месяц старта | H1: Месяц окончания | I1: Результат/мес | J1: Расход/мес без разового | K1: CPM: цена 1 000 показов или просмотров, ₽ | L1: Источник / расчёт (ссылки — лист «Источники»)
A2: Привлечение мастеров (результат — регистрации мастеров)
A3: Таргет VK на мастеров | B3: Мастера маникюра, бровей, ресниц по интересам и сообществам | D3: 90000 | E3: =IFERROR(D3/K3*1000,0) -> 789473.68 | F3: =K3/1000/1000 -> 0.000114 | G3: 1 | H3: 36 | I3: =E3*F3 -> 90 | J3: =D3 -> 90000 | K3: 114 | L3: CPM VK Рекламы — click.ru, 2-й кв. 2026 (113,9 ₽). Стоимость регистрации мастера — 1 000 ₽: нижняя граница CPL в B2B для VK Рекламы (1 000–5 000 ₽, PressStart Digital, 2025–2026). Конверсия из показа в регистрацию = CPM / 1 000 / CPL ≈ 0,011%.
A4: Telegram Ads | B4: Реклама в каналах для бьюти-мастеров | D4: 30000 | E4: =IFERROR(D4/K4*1000,0) -> 99337.748 | F4: 0.00049 | G4: 1 | H4: 36 | I4: =E4*F4 -> 48.675497 | J4: =D4 -> 30000 | K4: 302 | L4: CPM: 3,2 € (средний для «Здоровье и фитнес», eLama, янв. 2026) × 94,32 ₽ (курс ЦБ, 04.10.2026). Конверсия из показа в регистрацию 0,049% — [допущение]
A5: Блогеры-мастера | B5: Обзоры кабинета мастера у мастеров с аудиторией коллег | D5: 15000 | E5: =IFERROR(D5/K5*1000,0) -> 7500 | F5: 0.0015 | G5: 2 | H5: 36 | I5: =E5*F5 -> 11.25 | J5: =D5 -> 15000 | K5: 2000 | L5: Цена просмотра ≈2 ₽ в лайфстайл-нишах (Unisender: 1–2 ₽; Workspace 2026: 2,8 ₽ в маркетинге). Конверсия из просмотра в регистрацию 0,15% — [допущение]
A6: Курсы и колледжи | B6: Промокоды выпускникам, мастер-классы в школах маникюра и бровей | C6: 30000 | D6: 10000 | E6: 200 | F6: 0.1 | G6: 2 | H6: 36 | I6: =E6*F6 -> 20 | J6: =D6 -> 10000 | L6: [допущение] 5 школ-партнёров × 40 выпускников в месяц; 10% регистрируются по промокоду. Разово — материалы и мастер-классы
A7: Посты в Telegram-каналах и чатах мастеров | B7: Посты в каналах и чатах для бьюти-мастеров | D7: 15000 | E7: =IFERROR(D7/K7*1000,0) -> 10000 | F7: 0.00036 | G7: 1 | H7: 36 | I7: =E7*F7 -> 3.6 | J7: =D7 -> 15000 | K7: 1500 | L7: Цена просмотра 1–2 ₽ в лайфстайл-каналах (Unisender 2026, эксперт BOcean), берём 1,5 ₽. Конверсия из просмотра в регистрацию 0,036% — [допущение]
A8: Привлечение клиентов в каталог (результат — новые клиенты)
A9: Геореклама в Яндекс Картах | B9: Баннер каталога в районах с мастерами | D9: 17500 | E9: =IFERROR(D9/K9*1000,0) -> 87500 | F9: 0.00086 | G9: 3 | H9: 36 | I9: =E9*F9 -> 75.25 | J9: =D9 -> 17500 | K9: 200 | L9: От 200 ₽ за 1 000 показов, минимальный заказ 17 500 ₽ (Skillbox, данные 2023). Конверсия из показа в первую запись 0,086% — [допущение]
A10: Таргет VK на клиентов | B10: Женщины 20–45 лет в Москве, интерес к маникюру и бьюти | D10: 70000 | E10: =IFERROR(D10/K10*1000,0) -> 614035.09 | F10: 0.00076 | G10: 3 | H10: 36 | I10: =E10*F10 -> 466.66667 | J10: =D10 -> 70000 | K10: 114 | L10: [решение команды] Основной клиентский канал: самая низкая цена клиента. При росте бюджета цена клиента может вырасти — проверить на пилоте. CPM 113,9 ₽ — VK Реклама, click.ru, 2-й кв. 2026. Конверсия из показа в первую запись 0,076% — [допущение]: в кейсе таргета для студии маникюра выходило ≈0,036%, у каталога с подбором по манере закладываем выше. Клиентов пускаем с 3-го месяца, когда в каталоге уже есть мастера
A13: Номер месяца | B13: 0 | C13: 1 | D13: 2 | E13: 3 | F13: 4 | G13: 5 | H13: 6 | I13: 7 | J13: 8 | K13: 9 | L13: 10 | M13: 11 | N13: 12 | O13: 13 | P13: 14 | Q13: 15 | R13: 16 | S13: 17 | T13: 18 | U13: 19 | V13: 20 | W13: 21 | X13: 22 | Y13: 23 | Z13: 24 | AA13: 25 | AB13: 26 | AC13: 27 | AD13: 28 | AE13: 29 | AF13: 30 | AG13: 31 | AH13: 32 | AI13: 33 | AJ13: 34 | AK13: 35 | AL13: 36
A14: Регистрации мастеров | B14: =SUMPRODUCT(($G$3:$G$7<=B$13)*((($H$3:$H$7="")+($H$3:$H$7>=B$13))>0)*$I$3:$I$7) -> 0 | C14: =SUMPRODUCT(($G$3:$G$7<=C$13)*((($H$3:$H$7="")+($H$3:$H$7>=C$13))>0)*$I$3:$I$7) -> 142.2755 | D14: =SUMPRODUCT(($G$3:$G$7<=D$13)*((($H$3:$H$7="")+($H$3:$H$7>=D$13))>0)*$I$3:$I$7) -> 173.5255 | E14: =SUMPRODUCT(($G$3:$G$7<=E$13)*((($H$3:$H$7="")+($H$3:$H$7>=E$13))>0)*$I$3:$I$7) -> 173.5255 | F14: =SUMPRODUCT(($G$3:$G$7<=F$13)*((($H$3:$H$7="")+($H$3:$H$7>=F$13))>0)*$I$3:$I$7) -> 173.5255 | G14: =SUMPRODUCT(($G$3:$G$7<=G$13)*((($H$3:$H$7="")+($H$3:$H$7>=G$13))>0)*$I$3:$I$7) -> 173.5255 | H14: =SUMPRODUCT(($G$3:$G$7<=H$13)*((($H$3:$H$7="")+($H$3:$H$7>=H$13))>0)*$I$3:$I$7) -> 173.5255 | I14: =SUMPRODUCT(($G$3:$G$7<=I$13)*((($H$3:$H$7="")+($H$3:$H$7>=I$13))>0)*$I$3:$I$7) -> 173.5255 | ... AL14: =SUMPRODUCT(($G$3:$G$7<=AL$13)*((($H$3:$H$7="")+($H$3:$H$7>=AL$13))>0)*$I$3:$I$7) -> 173.5255
A15: Расходы на мастеров | B15: =SUMPRODUCT(($G$3:$G$7<=B$13)*((($H$3:$H$7="")+($H$3:$H$7>=B$13))>0)*$J$3:$J$7)+SUMPRODUCT(($G$3:$G$7=B$13)*$C$3:$C$7) -> 0 | C15: =SUMPRODUCT(($G$3:$G$7<=C$13)*((($H$3:$H$7="")+($H$3:$H$7>=C$13))>0)*$J$3:$J$7)+SUMPRODUCT(($G$3:$G$7=C$13)*$C$3:$C$7) -> 135000 | D15: =SUMPRODUCT(($G$3:$G$7<=D$13)*((($H$3:$H$7="")+($H$3:$H$7>=D$13))>0)*$J$3:$J$7)+SUMPRODUCT(($G$3:$G$7=D$13)*$C$3:$C$7) -> 190000 | E15: =SUMPRODUCT(($G$3:$G$7<=E$13)*((($H$3:$H$7="")+($H$3:$H$7>=E$13))>0)*$J$3:$J$7)+SUMPRODUCT(($G$3:$G$7=E$13)*$C$3:$C$7) -> 160000 | F15: =SUMPRODUCT(($G$3:$G$7<=F$13)*((($H$3:$H$7="")+($H$3:$H$7>=F$13))>0)*$J$3:$J$7)+SUMPRODUCT(($G$3:$G$7=F$13)*$C$3:$C$7) -> 160000 | G15: =SUMPRODUCT(($G$3:$G$7<=G$13)*((($H$3:$H$7="")+($H$3:$H$7>=G$13))>0)*$J$3:$J$7)+SUMPRODUCT(($G$3:$G$7=G$13)*$C$3:$C$7) -> 160000 | H15: =SUMPRODUCT(($G$3:$G$7<=H$13)*((($H$3:$H$7="")+($H$3:$H$7>=H$13))>0)*$J$3:$J$7)+SUMPRODUCT(($G$3:$G$7=H$13)*$C$3:$C$7) -> 160000 | I15: =SUMPRODUCT(($G$3:$G$7<=I$13)*((($H$3:$H$7="")+($H$3:$H$7>=I$13))>0)*$J$3:$J$7)+SUMPRODUCT(($G$3:$G$7=I$13)*$C$3:$C$7) -> 160000 | ... AL15: =SUMPRODUCT(($G$3:$G$7<=AL$13)*((($H$3:$H$7="")+($H$3:$H$7>=AL$13))>0)*$J$3:$J$7)+SUMPRODUCT(($G$3:$G$7=AL$13)*$C$3:$C$7) -> 160000
A16: Новые клиенты | B16: =SUMPRODUCT(($G$9:$G$10<=B$13)*((($H$9:$H$10="")+($H$9:$H$10>=B$13))>0)*$I$9:$I$10) -> 0 | C16: =SUMPRODUCT(($G$9:$G$10<=C$13)*((($H$9:$H$10="")+($H$9:$H$10>=C$13))>0)*$I$9:$I$10) -> 0 | D16: =SUMPRODUCT(($G$9:$G$10<=D$13)*((($H$9:$H$10="")+($H$9:$H$10>=D$13))>0)*$I$9:$I$10) -> 0 | E16: =SUMPRODUCT(($G$9:$G$10<=E$13)*((($H$9:$H$10="")+($H$9:$H$10>=E$13))>0)*$I$9:$I$10) -> 541.91667 | F16: =SUMPRODUCT(($G$9:$G$10<=F$13)*((($H$9:$H$10="")+($H$9:$H$10>=F$13))>0)*$I$9:$I$10) -> 541.91667 | G16: =SUMPRODUCT(($G$9:$G$10<=G$13)*((($H$9:$H$10="")+($H$9:$H$10>=G$13))>0)*$I$9:$I$10) -> 541.91667 | H16: =SUMPRODUCT(($G$9:$G$10<=H$13)*((($H$9:$H$10="")+($H$9:$H$10>=H$13))>0)*$I$9:$I$10) -> 541.91667 | I16: =SUMPRODUCT(($G$9:$G$10<=I$13)*((($H$9:$H$10="")+($H$9:$H$10>=I$13))>0)*$I$9:$I$10) -> 541.91667 | ... AL16: =SUMPRODUCT(($G$9:$G$10<=AL$13)*((($H$9:$H$10="")+($H$9:$H$10>=AL$13))>0)*$I$9:$I$10) -> 541.91667
A17: Расходы на клиентов | B17: =SUMPRODUCT(($G$9:$G$10<=B$13)*((($H$9:$H$10="")+($H$9:$H$10>=B$13))>0)*$J$9:$J$10)+SUMPRODUCT(($G$9:$G$10=B$13)*$C$9:$C$10) -> 0 | C17: =SUMPRODUCT(($G$9:$G$10<=C$13)*((($H$9:$H$10="")+($H$9:$H$10>=C$13))>0)*$J$9:$J$10)+SUMPRODUCT(($G$9:$G$10=C$13)*$C$9:$C$10) -> 0 | D17: =SUMPRODUCT(($G$9:$G$10<=D$13)*((($H$9:$H$10="")+($H$9:$H$10>=D$13))>0)*$J$9:$J$10)+SUMPRODUCT(($G$9:$G$10=D$13)*$C$9:$C$10) -> 0 | E17: =SUMPRODUCT(($G$9:$G$10<=E$13)*((($H$9:$H$10="")+($H$9:$H$10>=E$13))>0)*$J$9:$J$10)+SUMPRODUCT(($G$9:$G$10=E$13)*$C$9:$C$10) -> 87500 | F17: =SUMPRODUCT(($G$9:$G$10<=F$13)*((($H$9:$H$10="")+($H$9:$H$10>=F$13))>0)*$J$9:$J$10)+SUMPRODUCT(($G$9:$G$10=F$13)*$C$9:$C$10) -> 87500 | G17: =SUMPRODUCT(($G$9:$G$10<=G$13)*((($H$9:$H$10="")+($H$9:$H$10>=G$13))>0)*$J$9:$J$10)+SUMPRODUCT(($G$9:$G$10=G$13)*$C$9:$C$10) -> 87500 | H17: =SUMPRODUCT(($G$9:$G$10<=H$13)*((($H$9:$H$10="")+($H$9:$H$10>=H$13))>0)*$J$9:$J$10)+SUMPRODUCT(($G$9:$G$10=H$13)*$C$9:$C$10) -> 87500 | I17: =SUMPRODUCT(($G$9:$G$10<=I$13)*((($H$9:$H$10="")+($H$9:$H$10>=I$13))>0)*$J$9:$J$10)+SUMPRODUCT(($G$9:$G$10=I$13)*$C$9:$C$10) -> 87500 | ... AL17: =SUMPRODUCT(($G$9:$G$10<=AL$13)*((($H$9:$H$10="")+($H$9:$H$10>=AL$13))>0)*$J$9:$J$10)+SUMPRODUCT(($G$9:$G$10=AL$13)*$C$9:$C$10) -> 87500
A18: Маркетинговые расходы всего | B18: =B15+B17 -> 0 | C18: =C15+C17 -> 135000 | D18: =D15+D17 -> 190000 | E18: =E15+E17 -> 247500 | F18: =F15+F17 -> 247500 | G18: =G15+G17 -> 247500 | H18: =H15+H17 -> 247500 | I18: =I15+I17 -> 247500 | ... AL18: =AL15+AL17 -> 247500
A19: CPL мастера, ₽/регистрация | B19: =IFERROR(B15/B14,0) -> 0 | C19: =IFERROR(C15/C14,0) -> 948.86332 | D19: =IFERROR(D15/D14,0) -> 1094.94 | E19: =IFERROR(E15/E14,0) -> 922.0547 | F19: =IFERROR(F15/F14,0) -> 922.0547 | G19: =IFERROR(G15/G14,0) -> 922.0547 | H19: =IFERROR(H15/H14,0) -> 922.0547 | I19: =IFERROR(I15/I14,0) -> 922.0547 | ... AL19: =IFERROR(AL15/AL14,0) -> 922.0547
A20: Стоимость клиента, ₽ | B20: =IFERROR(B17/B16,0) -> 0 | C20: =IFERROR(C17/C16,0) -> 0 | D20: =IFERROR(D17/D16,0) -> 0 | E20: =IFERROR(E17/E16,0) -> 161.46394 | F20: =IFERROR(F17/F16,0) -> 161.46394 | G20: =IFERROR(G17/G16,0) -> 161.46394 | H20: =IFERROR(H17/H16,0) -> 161.46394 | I20: =IFERROR(I17/I16,0) -> 161.46394 | ... AL20: =IFERROR(AL17/AL16,0) -> 161.46394
B22: Регистрации мастеров | C22: Расходы на мастеров | D22: CPL мастера | E22: Новые клиенты | F22: Расходы на клиентов | G22: Стоимость клиента
A23: Итого год 1 | B23: =SUM(B14:N14) -> 2051.056 | C23: =SUM(B15:N15) -> 1925000 | D23: =IFERROR(C23/B23,0) -> 938.54095 | E23: =SUM(B16:N16) -> 5419.1667 | F23: =SUM(B17:N17) -> 875000 | G23: =IFERROR(F23/E23,0) -> 161.46394
A24: Итого год 2 | B24: =SUM(O14:Z14) -> 2082.306 | C24: =SUM(O15:Z15) -> 1920000 | D24: =IFERROR(C24/B24,0) -> 922.0547 | E24: =SUM(O16:Z16) -> 6503 | F24: =SUM(O17:Z17) -> 1050000 | G24: =IFERROR(F24/E24,0) -> 161.46394
A25: Итого год 3 | B25: =SUM(AA14:AL14) -> 2082.306 | C25: =SUM(AA15:AL15) -> 1920000 | D25: =IFERROR(C25/B25,0) -> 922.0547 | E25: =SUM(AA16:AL16) -> 6503 | F25: =SUM(AA17:AL17) -> 1050000 | G25: =IFERROR(F25/E25,0) -> 161.46394
A26: Результат в месяц = охват × конверсия (регистрация мастера или первая запись клиента). Охват платных каналов = месячный бюджет / CPM × 1 000. Конверсия — сразу из показа или просмотра в результат. Мастеров привлекаем с 1-го месяца (после MVP), клиентов — с 3-го, когда каталог заполнен. Разовый бюджет списывается в месяц старта. «[допущение]» — цифру нужно проверить тестом. Итоги по годам (строки 23–25) — до учёта насыщения рынка, холодного старта и роста клиентского бюджета; итог с учётом всего этого — лист «3 года подробно», строки 5, 14 и 30.

Sheet Источники
A1: Источник | B1: Что взято | C1: Где используется | D1: Ссылка
A2: Росстат через Т—Ж, «Демография Москвы» | B2: 7,10 млн женщин в Москве на 1.01.2025. Доля 20–45 лет ≈35% (≈2,5 млн) — наша оценка: публичной разбивки по возрасту нет | C2: Вводные!B53 | D2: https://t-j.ru/demography-moscow/
A3: ДПиИР Москвы через РБК Отрасли (апрель 2025) | B3: Более 50 тыс. самозанятых в бьюти-индустрии Москвы; с мастерами без регистрации берём 65 тыс. (коридор 50–85 тыс. — оценка команды) | C3: Вводные!B3 | D3: https://www.rbc.ru/industries/news/68623d939a79476674ac20ba
A4: Data Insight и Авито Услуги (Коммерсантъ, 09.08.2022) | B4: 42% бьюти-мастеров ищут клиентов на Авито (опора для доли 60% онлайн; сама доля 60% и доля 70% мастеров в наших услугах — допущения команды, первоисточника нет) | C4: Вводные!B4, Вводные!B5 | D4: https://www.kommersant.ru/doc/5502865
A5: СберАналитика, траты на красоту (янв.–нояб. 2025) | B5: Средний чек в салоне в Москве 3 190 ₽ | C5: Вводные!B7 | D5: https://sberanalytics.ru/researches/beauty-and-fashion-spendings
A6: Опрос Авито, 10 000 женщин (Mail.ru Финансы) | B6: 14 визитов в год | C6: Вводные!B8 | D6: https://finance.mail.ru/article/zhiteli-moskvyi-v-srednem-tratyat-13-tyis-rublej-v-mesyats-na-byuti-protseduryi-69201863/
A7: YCLIENTS через Webgard (сверено 24.09.2026) | B7: Ориентир цены: тариф частного специалиста от 1 600 ₽/мес. Наши 990 ₽ подписки и 1 490 ₽ продвижения — решение команды, ниже ближайшего аналога; проверим на пилоте | C7: Вводные!B21, Вводные!B22 | D7: https://webgard.ru/blog/biznes/yclients/
A8: Профи.ру через HelmePro (12.07.2026) | B8: Ориентир: мастер платит ≈50–300 ₽ за каждый отклик на заказ, то есть платное продвижение для мастеров рынку привычно. Потолок доли 25% опирается на опрос Авито (строки 48–49) | C8: Вводные!B23 | D8: https://helmepro.ru/stati/profi-ru-dlya-ispolniteley/
A9: Анкетолог, опрос о парикмахерских (2021, 2 200 чел., города 100 тыс.+) | B9: Контекст для цели: 64% клиентов имеют постоянного мастера, 21% — нет, 39% выбирают мастера по личным качествам. Цель 60% первых визитов «совпали» — целевой показатель команды, рыночного первоисточника нет; проверим на пилоте | C9: Вводные!B15 | D9: https://iom.anketolog.ru/2021/05/04/parikmaherskie
A10: НК РФ (гл. 26.2, ст. 346.18; гл. 34) | B10: УСН 15%, минимальный налог 1%, страховые взносы 30% | C10: Вводные!B27, Вводные!B28, Вводные!B31 | D10: https://www.consultant.ru/document/cons_doc_LAW_28165/
A11: PMI, «Accurate estimates — the 20 percent solution» | B11: Резерв 20% бюджета проекта (10% на известные и 10% на неизвестные риски) | C11: Вводные!B32 → Разработка!I9 | D11: https://www.pmi.org/learning/library/accurate-estimates-20-percent-solution-9805
A12: click.ru, «Пульс click.ru», 2-й кв. 2026 | B12: VK Реклама: CPM 113,9 ₽, CTR 1,24% | C12: Маркетинг!K3, F3, K10 (CPM VK) | D12: https://blog.click.ru/analytics/issledovanie-klyuchevyh-pokazateley-internet-reklamy/
... A51: Простые решения (spmag.ru), 08.07.2026: закон № 228-ФЗ от 04.07.2026 | B51: Порог 20 млн ₽ сохранён до 2028 года; 15 млн ₽ в 2029-м, 10 млн ₽ с 2030-го | C51: Вводные!B74:B76 | D51: https://spmag.ru/news/usn-porog-vyruchki-dlya-osvobozhdeniya-ot-nds-mogut-sohranit
